Workbook

Sheet Распределение объектов
B1: № | C1: Объект | D1: Заказчик | E1: Договор / адрес
B2: =ROW()-1 -> 1 | C2: Алтуфьевское шоссе | D2: ООО "ПИК-УК"
B4: =ROW()-1 -> 3 | C4: Амурский парк | D4: ООО "ГЛОБАЛСТРОЙТЕХ"
E5: ул. Амурская, вл. 2, Блок 1, корп. 1.1-1.5. | F5: ул. Амурская, вл.2А, Блок 4, корп. 4.1-4.5. | G5: г. Москва, ул. Амурская, вл. 2, ДОО на 250 мест. | H5: ул. Амурская, вл. 2, Блок 4, этап 4.1 с БКФН и подз. паркингом.
B6: =ROW()-1 -> 5 | C6: Большая Академическая | D6: ООО "ПИК-УК"
E7: г. Москва, 3-й Нижнелихоборский пр-д, вл. 1, корп. 3.1-3.4. | F7: 3-й Нижнелихоборский пр-д, вл. 1, корп. 3.1-3.4 | G7: г. Москва, 3-й Нижнелихоборский пр-д, вл. 1, площадка. | H7: г. Москва, 3-й Нижнелихоборский пр-д, вл. 1, площадка.
B8: =ROW()-1 -> 7 | C8: Бусиновский парк (Ижорская, Коровинское) | D8: ООО "ПИК-УК"
B10: =ROW()-1 -> 9 | C10: Волжский парк (1-й Грайвороновский) | D10: ООО "ПИК-МЕНЕДЖМЕНТ" | E10: В5-СП-СК от 28.10.2022 №ВП5.2-СКАЛА-ЗР от 28.06.2023 | F10: № ВП6.2-СКАЛА-СПС 11.12.2024 года ВП6.2-СКАЛА-МР от 16.12.2024 года
E11: г. Москва, 1-й Грайвороновский пр-д, вл. 3, общедомовой к корп. 5.1-5.4 | F11: г. Москва, 1-й Грайвороновский пр-д, вл. 3, корп. 6.2 | G11: г. Москва, 1-й Грайвороновский пр-д, вл. 3, корп. 11, паркинг на 425 м/м | H11: г. Москва, 1-й Грайвороновский пр-д, вл. 3, площадка
B12: =ROW()-1 -> 11 | C12: Грин Парк | D12: ООО "ПИК-МЕНЕДЖМЕНТ"
E13: ВДНХ, ул. Сельскохозяйственная, вл. 35, оч. 3, БНК на 270 мест с СОШ на 825 мест. | F13: г. Москва, ВДНХ, ул. Сельскохозяйственная, вл. 35, оч. 3, Блок 8. | G13: г. Москва, ВДНХ, вл. 35, оч. 3, ДОУ 3. | H13: г. Москва, ВДНХ, ул. Сельскохозяйственная, вл. 35, оч. 3, СОШ (825 мест).
B14: =ROW()-1 -> 13 | C14: Зеленоград (Зелёный парк) | D14: ООО "ПИК-УК"
B16: =ROW()-1 -> 15 | C16: Кавказский бульвар | D16: ООО "ПИК-УК"
E17: г. Москва, Кавказский б-р, вл. 51, площадка | F17: г. Москва, Кавказский б-р, вл. 51, ДОО на 250 мест, Этап 3.2
B18: =ROW()-1 -> 17 | C18: Красноказарменная | D18: ООО "ПИК-МЕНЕДЖМЕНТ"
E19: г. Москва, Красноказарменная 15, Этап 3, ДОО на 110 мест | F19: г. Москва, Красноказарменная 15, площадка
B20: =ROW()-1 -> 19 | C20: Кронштадский 11 | D20: ООО "ГЛОБАЛСТРОЙТЕХ"
B22: =ROW()-1 -> 21 | C22: Ленингадское шоссе (КИН) | D22: ООО "ПИК-УК"
E23: Ленинградское шоссе 67.
B24: =ROW()-1 -> 23 | C24: Люберецкий | D24: ООО "ГП-МО"
E25: Люберцы, ЖК Люберецкий, площадка. | F25: г. Люберцы, ЖК Люберецкий, мобилизация корпус 9.2.
B26: =ROW()-1 -> 25 | C26: Люблинский парк | D26: ООО "ГЛОБАЛСТРОЙТЕХ"
B28: =ROW()-1 -> 27 | C28: Матвеевский парк ( Vangarden, Среда на Лобачевского) | D28: ООО "ПИК-УК"
E29: г. Москва, Очаковское ш., вл. 3, 3А, 5, площадка 77:07:0012008:4340, 77:07:0012008:4342, 77:07:0012008:4323, 77:07:0012008:4403, 77:07:0012008:4409, 77:07:0012008:4417, 77:07:0012008:4406, 77:07:0012008:4412 | F29: г. Москва, Очаковское ш., вл. 3, 3А, 5, площадка Городок | G29: г. Москва, Очаковское ш., вл. 3, 3А, 5. Среда | H29: г. Москва, Очаковское ш., вл. 3, 3а, 5, площадка 4 очередь
B30: =ROW()-1 -> 29 | C30: Моментс (Красногорский, Волоколамское ш.) | D30: ООО "ПИК-УК"
E31: г. Москва, Волоколамское ш., вл. 28, площадка
B32: =ROW()-1 -> 31 | C32: Москворечье (Котляковский) | D32: ООО "ПИК-МЕНЕДЖМЕНТ"
E33: г. Москва, ул. Котляковская, площадка | F33: ЖК Московречье, ул.Котляковская, площадка.
B34: =ROW()-1 -> 33 | C34: Первый Московский фаза 7 к3 | D34: ООО "НДК"
B36: =ROW()-1 -> 35 | C36: Первый московский Фаза 9 к 1-2 | D36: ООО "НДК"
B38: =ROW()-1 -> 37 | C38: Первый московский Фаза 9 к 3-4 | D38: ООО "НДК"
B40: =ROW()-1 -> 39 | C40: Полярная | D40: ООО "ПИК-МЕНЕДЖМЕНТ"
E41: ул. Полярная, вл. 25, площадка.
C42: Рассказовка фаза 12 | D42: ООО "НДК"
B44: =ROW()-1 -> 43 | C44: Рассказовка фаза 13 | D44: ООО "НДК"
B46: =ROW()-1 -> 45 | C46: Рассказовка фаза 18 | D46: ООО "НДК"
B48: =ROW()-1 -> 47 | C48: Саларьево парк | D48: ООО "ПИК-МЕНЕДЖМЕНТ"
E49: Многоэтажный жилой дом, корпус 74 | F49: д. Саларьево, 14 очередь, корп. 83 | G49: д. Саларьево, 11-я очередь, корп. 57 | H49: корпус 69 | I49: корпус 56 | J49: корпус 86 | K49: корпус 20 | L49: д. Саларьево, 11-я очередь | M49: д. Саларьево, 12-я очередь | N49: д. Саларьево, 13-я очередь | O49: д. Саларьево, 14-я очередь | P49: д. Саларьево, площадка
B50: =ROW()-1 -> 49 | C50: Северный терминал (Ижорская, Коровинское) | D50: ООО "ПИК-УК"
B52: =ROW()-1 -> 51 | C52: Середневский лес (Филимонковское, ОАО "Марьинская птицефабрика") | D52: ООО "ПИК-МЕНЕДЖМЕНТ"
...

Sheet Лист2
A1: Волжский парк | B1: В5-СП-СК | C1: г. Москва, 1-й Грайвороновский пр-д, вл. 3, общедомовой к корп. 5.1-5.4
A2: Волжский парк | B2: ВП-М-СК | C2: г. Москва, 1-й Грайвороновский пр-д, вл. 3, площадка
A3: Волжский парк | B3: ВП5.2-СКАЛА-ЗР | C3: г. Москва, 1-й Грайвороновский пр-д, вл. 3, корп. 5.2
A4: Волжский парк | B4: ВП6.2-СКАЛА-СПС | C4: г. Москва, 1-й Грайвороновский пр-д, вл. 3, корп. 6.1, 6.2
A5: Волжский парк | B5: ВП6.2-СКАЛА-МР | C5: г. Москва, 1-й Грайвороновский пр-д, вл. 3, 6-ой очереди
A6: Волжский парк | B6: ВП7-СКАЛА-ССП | C6: г. Москва, 1-й Грайвороновский пр-д, вл. 3, корп. 7, ДОУ на 300 мест
A7: Волжский парк | B7: ВП5.1-5.4-СКАЛА-ССП | C7: г. Москва, 1-й Грайвороновский пр-д, вл. 3, общедомовой к корп. 5.1-5.4
A8: Волжский парк | B8: ВП5.1-5.4-СКАЛА-МЗ | C8: г. Москва, 1-й Грайвороновский пр-д, вл. 3, общедомовой к корп. 5.1-5.4
A9: Волжский парк | B9: ВП-СКАЛА-ВЖББ-ПЛОЩ | C9: г. Москва, 1-й Грайвороновский пр-д, вл. 3, площадка
A10: Волжский парк | B10: ВП11-СКАЛА-СКПТ | C10: г. Москва, 1-й Грайвороновский пр-д, вл. 3, корп. 11, паркинг на 425 м/м
A11: Волжский парк | B11: 22443398 | C11: г. Москва, 1-й Грайвороновский пр-д, вл. 3, корп. 11, паркинг на 425 м/м
A12: Волжский парк | B12: ВП5.1-5.4-СКАЛА-ССП | C12: г. Москва, 1-й Грайвороновский пр-д, вл. 3, общедомовой к корп. 5.1-5.4
... A16: Волжский парк | B16: ВП6.2-СКАЛА-МР | C16: г. Москва, 1-й Грайвороновский пр-д, вл. 3, корп. 6.2
A19: Кавказский бульвар 51 | B19: КБ51-СКЛ-Экс/ДОО | C19: 45097 | D19: г. Москва, Кавказский б-р, вл. 51, ДОО на 250 мест, Этап 3.2 б
A20: Кавказский бульвар 51 | B20: КБ51-СКЛ-Моб/ДОО | C20: 45097 | D20: г. Москва, Кавказский б-р, вл. 51, ДОО на 250 мест, Этап 3.2 б
A21: Кавказский бульвар 51 | B21: КБ51-СКЛ-Мех/ДОО | C21: 45097 | D21: г. Москва, Кавказский б-р, вл. 51, ДОО на 250 мест, Этап 3.2 б
A22: Кавказский бульвар 51 | B22: КБ51-Скала-МБЛЗ/эт2 | C22: 45399 | D22: г. Москва, Кавказский б-р, вл. 51, 1-я оч., этап 2, корп. 1.5, 1.6 с подземным паркингом на 133 м/м
A23: Кавказский бульвар 51 | B23: КБ51-Скала-РВР-МУС/эт2 | C23: 45566 | D23: г. Москва, Кавказский б-р, вл. 51, 1-я оч., этап 2, корп. 1.5, 1.6 с подземным паркингом на 133 м/м
A24: Кавказский бульвар 51 | B24: КБ51-СКЛ-Мех.5087447/пл | C24: 45559 | D24: г. Москва, Кавказский б-р, вл. 51, площадка
A25: Кавказский бульвар 51 | B25: КБ51-СКЛ-ВДПР/пл | C25: 45593 | D25: г. Москва, Кавказский б-р, вл. 51, площадка
A26: Кавказский бульвар 51 | B26: КБ51-Скала-Экс/пл | C26: 45736 | D26: г. Москва, Кавказский б-р, вл. 51, площадка
A27: Кавказский бульвар 51 | B27: КБ51-Скала-РВР-МУС/эт2 | C27: 45566 | D27: г. Москва, Кавказский б-р, вл. 51, 1-я оч., этап 2, корп. 1.5, 1.6 с подземным паркингом на 133 м/м
A28: Кавказский бульвар 51 | B28: КБ51-СКЛ-Экс/ДОО | C28: 45097 | D28: г. Москва, Кавказский б-р, вл. 51, ДОО на 250 мест, Этап 3.2 б
A30: Комьюнити центр ОМА | B30: 18183437 | C30: 45261 | D30: г. Москва, Очаковское ш., ТЦ "Матвеевский"
A32: Матвеевский/Вангарден | B32: СК-Моб-ОЧш | C32: 44256 | D32: г. Москва, Очаковское ш., вл. 3, 3А, 5, площадка
... A115: Vangarden | B115: СК-МОБ/ОЧШ-5.1-5.8 | C115: 45365 | D115: г. Москва, Очаковское ш., вл. 3, 3А, 5, площадка

Sheet Таблицы
B2: Поставка материалов на площадки СКАЛА
B3: Реестр авансов СКАЛА
B4: К СОВЕЩАНИЮ
B5: Согласование КС СКАЛА

Sheet Список договоров
J1: РЕЕСТР ДЕЙСТВУЮЩИХ КОНТРАКТОВ ООО "СКАЛА"
J2: Актуальная инфомация на 30.09.2026 | V2: =134682487.75-2901585.12-1019567.64 -> 130761335 | W2: =173621682.52-556937.98-1557100 -> 1.7150764e+08 | X2: =122304460.57-390000 -> 1.2191446e+08 | Y2: =124683109.69-1019567.64 -> 1.2366354e+08 | Z2: =105211629.64-2621909.5 -> 1.0258972e+08 | AA2: 1.0479147e+08
V3: 2 квартал 2026 | Y3: 3 квартал 2026
A4: ПТО | B4: № п/п | C4: Объекты Адрес/корпус/очередь | D4: Заказчик | E4: Статус | F4: Договор | G4: Объект и адрес по договору | H4: Адрес ПИК | I4: Вид работ | J4: ГПР | M4: Сумма договора, руб | N4: Сумма договора, руб на 21.04.2026 | O4: ПДЦ 21.04.2026 - 04.05.2026 | P4: ПДЦ 04.05.2026 - 15.06.2026 | Q4: ПДЦ 16.06.2026-31.07.2026 | R4: ПДЦ актуально на 30.09.26 | S4: Шаблон | T4: Выполнено, руб | U4: Актуально на 21.04.2026 | V4: Выполнение апрель | W4: Выполнение май | X4: Выполнение июнь | Y4: Выполнение июль | Z4: Выполнение август | AA4: Выполнение сентябрь | AB4: Шаблон | AD4: РП/Прораб | AP4: Примечания
J5: Общая стоимость контрактов, руб. | M5: =M7+M155 -> 3338915348 | N5: =N7+N155 -> 3003467463 | O5: =O7+O155 -> 5.8096377e+08 | P5: =P7+P155 -> 2.8940028e+08 | Q5: =Q7+Q155 -> 1.4069944e+08 | R5: =R7+R155 -> 1.9925049e+08 | S5: =S7+S155 -> 0 | T5: =SUM(U5:AA5) -> 2330678249 | U5: =U7+U155 -> 1563409969 | V5: =V7+V155 -> 1.2200521e+08 | W5: =W7+W155 -> 1.7048808e+08 | X5: =X7+X155 -> 1.2191446e+08 | Y5: =Y7+Y155 -> 1.2366354e+08 | Z5: =Z7+Z155 -> 1.0258972e+08 | AA5: =AA7+AA155 -> 1.2660727e+08 | AB5: =AB7+AB155 -> 0
J6: ЗАКАЗЧИК ПИК | V6: =SUM(V5:X5) -> 4.1440775e+08 | Y6: =SUM(Y5:AA5) -> 3.5286053e+08
J7: Общая стоимость по Заказчику ПИК, руб. | M7: =M8+M15+M20+M35+M37+M57+M82+M86+M95+M108+M111+M114+M117+M122+M125+M129+M132+M54+M137+M148 -> 2529356221 | N7: =N8+N15+N20+N35+N37+N57+N82+N86+N95+N108+N111+N114+N117+N122+N125+N129+N132+N54+N137+N148 -> 2169570623 | O7: =O8+O15+O20+O35+O37+O57+O82+O86+O95+O108+O111+O114+O117+O122+O125+O129+O132+O54+O137+O148 -> 5.8096377e+08 | P7: =P8+P15+P20+P35+P37+P57+P82+P86+P95+P108+P111+P114+P117+P122+P125+P129+P132+P54+P137+P148 -> 2.6150338e+08 | Q7: =Q8+Q15+Q20+Q35+Q37+Q57+Q82+Q86+Q95+Q108+Q111+Q114+Q117+Q122+Q125+Q129+Q132+Q54+Q137+Q148 -> 1.4069944e+08 | R7: =R8+R15+R20+R35+R37+R57+R82+R86+R95+R108+R111+R114+R117+R122+R125+R129+R132+R54+R137+R148 -> 1.9925049e+08 | S7: =S8+S15+S20+S35+S37+S57+S82+S86+S95+S108+S111+S114+S117+S122+S125+S129+S132+S54+S137+S148 -> 0 | T7: =SUM(U7:AA7) -> 1877906095 | U7: =U8+U15+U20+U35+U37+U57+U82+U86+U95+U108+U111+U114+U117+U122+U125+U129+U132+U54+U137+U148 -> 1252888812 | V7: =V8+V15+V20+V35+V37+V57+V82+V86+V95+V108+V111+V114+V117+V122+V125+V129+V132+V54+V137+V148+V89+V151 -> 1.0119335e+08 | W7: =W8+W15+W20+W35+W37+W57+W82+W86+W95+W108+W111+W114+W117+W122+W125+W129+W132+W54+W137+W148+W89+W151 -> 1.5526138e+08 | X7: =X8+X15+X20+X35+X37+X57+X82+X86+X95+X108+X111+X114+X117+X122+X125+X129+X132+X54+X137+X148+X89+X151 -> 85071984 | Y7: =Y8+Y15+Y20+Y35+Y37+Y57+Y82+Y86+Y95+Y108+Y111+Y114+Y117+Y122+Y125+Y129+Y132+Y54+Y137+Y148+Y89+Y151 -> 1.1008544e+08 | Z7: =Z8+Z15+Z20+Z35+Z37+Z57+Z82+Z86+Z95+Z108+Z111+Z114+Z117+Z122+Z125+Z129+Z132+Z54+Z137+Z148+Z89+Z151 -> 84131515 | AA7: =AA8+AA15+AA20+AA35+AA37+AA57+AA82+AA86+AA95+AA108+AA111+AA114+AA117+AA122+AA125+AA129+AA132+AA54+AA137+AA148+AA89+AA151 -> 89273603 | AB7: =AB8+AB15+AB20+AB35+AB37+AB57+AB82+AB86+AB95+AB108+AB111+AB114+AB117+AB122+AB125+AB129+AB132+AB54+AB137+AB148 -> 0
A8: Н | B8: 1 | C8: Волжский парк | D8: ООО "ПИК-МЕНЕДЖМЕНТ" | L8: =T8/M8 -> 0.82897613 | M8: =SUM(M9:M14) -> 89525474 | N8: =SUM(N9:N14) -> 78450355 | O8: =SUM(O9:O14) -> 0 | P8: =SUM(P9:P14) -> 57242876 | Q8: =SUM(Q9:Q14) -> 0 | R8: =SUM(R9:R14) -> 0 | S8: =SUM(S9:S14) -> 0 | T8: =SUM(U8:AA8) -> 74214480 | U8: =SUM(U9:U14) -> 44432755 | V8: =SUM(V9:V14) -> 9312566.6 | W8: =SUM(W9:W14) -> 11430277 | X8: =SUM(X9:X14) -> 3918363.7 | Y8: =SUM(Y9:Y14) -> 1259122.4 | Z8: =SUM(Z9:Z14) -> 2602272.5 | AA8: =SUM(AA9:AA14) -> 1259122.4 | AB8: =SUM(AB9:AB14) -> 0 | AD8: Бочаев Руслан Хасанович/ -
A9: Н | B9: 1.1 | C9: Корпус 6 | E9: Активный | F9: ВП6.2-СКАЛА-МР от 16.12.2024 | G9: «Жилые дома Корпуса 6.1, 6.2. Этап 2. Корпус 6.2» по адресу: Москва, ЮВАО, Текстильщики, у-й Грайвороновский проезд, вл.3 | H9: г. Москва, 1-й Грайвороновский пр-д, вл. 3, 6-ой очереди | I9: Мобилизация | J9: 45611 | K9: 46203 | L9: =T9/M9 -> 0.67140797 | M9: =MAX(N9:R9) -> 21032010 | N9: 19044343 | P9: 21032010 | T9: =SUM(U9:AA9) -> 14121059 | U9: 6367680.4 | V9: 2082960 | W9: 3682752.2 | X9: 1987666.2 | Y9: =SUMIF('07.26'!$J$4:$J$1000,$F9,'07.26'!$M$4:$M$1000) -> 0 | Z9: =SUMIF('08.26'!$J$4:$J$1000,$F9,'08.26'!$M$4:$M$1000) -> 0 | AA9: =SUMIF('09.26'!$J$4:$J$1429,$F9,'09.26'!$M$4:$M$1429) -> 0
A10: Н | E10: Активный | F10: ВП6.2-СКАЛА-СПС от 11.12.2024 | G10: «Жилые дома Корпуса 6.1, 6.2. Этап 2. Корпус 6.2» по адресу: Москва, ЮВАО, Текстильщики, у-й Грайвороновский проезд, вл.3 | H10: г. Москва, 1-й Грайвороновский пр-д, вл. 3, корп. 6.1, 6.2 | I10: Эксплуатация | J10: 46023 | K10: 46112 | L10: =T10/M10 -> 0.88775846 | M10: =MAX(N10:R10) -> 36210866 | N10: 29591768 | P10: 36210866 | T10: =SUM(U10:AA10) -> 32146503 | U10: =24591768.04-V10 -> 17834209 | V10: 6757559.1 | W10: 2518244.9 | X10: 1259122.4 | Y10: =SUMIF('07.26'!$J$4:$J$1000,$F10,'07.26'!$M$4:$M$1000) -> 1259122.4 | Z10: =SUMIF('08.26'!$J$4:$J$1000,$F10,'08.26'!$M$4:$M$1000) -> 1259122.4 | AA10: =SUMIF('09.26'!$J$4:$J$1429,$F10,'09.26'!$M$4:$M$1429) -> 1259122.4 | AP10: НЗ на продление на подписании
A11: Н | B11: 1.2 | C11: Площадка | E11: Закрыт | F11: ВП-СКАЛА-ВЖББ-ПЛОЩ от 04.08.2025 | G11: объекты капитального строительства, расположенные на земельном (-ых) участке (-ах) с кадастровым (-и) номером (-ами): 77:04:0002005, по адресу: г. Москва, 1-й Грайвороновский пр-д, вл. 3, площадка | H11: г. Москва, 1-й Грайвороновский пр-д, вл. 3, площадка | I11: Мобилизация | J11: 45789 | K11: 46387 | L11: =T11/M11 -> 1 | M11: 1242897.7 | N11: 1292350.9 | T11: =SUM(U11:AA11) -> 1242897.7 | U11: 1242897.7 | Y11: =SUMIF('07.26'!$J$4:$J$1000,$F11,'07.26'!$M$4:$M$1000) -> 0 | Z11: =SUMIF('08.26'!$J$4:$J$1000,$F11,'08.26'!$M$4:$M$1000) -> 0 | AA11: =SUMIF('09.26'!$J$4:$J$1429,$F11,'09.26'!$M$4:$M$1429) -> 0 | AP11: пока на стопе, но в будущем работы планируются на площадке
A12: Н | E12: Закрыт | F12: ВП-СКАЛА-ЭКСП от 17.04.2026 | G12: объекты капитального строительства, расположенные на земельном (-ых) участке (-ах) с кадастровым (-и) номером (-ами): 77:04:0002005:16049, по адресу: г. Москва, 1-й Грайвороновский пр-д, вл. 3, площадка | H12: г. Москва, 1-й Грайвороновский пр-д, вл. 3, площадка | I12: Эксплуатация | J12: 46023 | K12: 46112 | L12: =T12/M12 -> 1 | M12: =MAX(N12:R12) -> 4436583.1 | N12: 4436583.1 | T12: =SUM(U12:AA12) -> 4436583.1 | U12: 0 | W12: 4436583.1 | Y12: =SUMIF('07.26'!$J$4:$J$1000,$F12,'07.26'!$M$4:$M$1000) -> 0 | Z12: =SUMIF('08.26'!$J$4:$J$1000,$F12,'08.26'!$M$4:$M$1000) -> 0 | AA12: =SUMIF('09.26'!$J$4:$J$1429,$F12,'09.26'!$M$4:$M$1429) -> 0 | AP12: подписали 21.04.2026, полностью забираем апрель
A13: Н | E13: Закрыт | F13: ВП5.2-СКАЛА-ЗР от 28.06.2023 | G13: объекты капитального строительства, расположенные на земельном (-ых) участке (-ах) с кадастровым (-и) номером (-ами): 77:04:0002005, по адресу: г. Москва, 1-й Грайвороновский пр-д, вл. 3, площадка | H13: г. Москва, 1-й Грайвороновский пр-д, вл. 3, площадка | I13: Мобилизация | J13: 45040 | K13: 46113 | L13: =T13/M13 -> 1 | M13: 2517807.5 | T13: =SUM(U13:AA13) -> 2517807.5 | U13: =2517807.54-V13 -> 2381547.5 | V13: 136260
A14: Н | B14: 1.3 | C14: Корпус 5 | E14: Активный | F14: В5-СП-СК от 06.10.2022 | G14: объект капитального строительства,предполагаемый к размещению на земельном (-ых) участке (-ах) с кадастровым (-и) номером (- ами): 77:04:0002005:10954, по адресу: г. Москва, 1-й Грайвороновский пр., вл. 3 (корп. 5.1, 5.2, 5.3, 5.4) | H14: г. Москва, 1-й Грайвороновский пр-д, вл. 3, общедомовой к корп. 5.1-5.4 | I14: Мобилизация | J14: 44805 | K14: 46387 | L14: =T14/M14 -> 0.81998657 | M14: =MAX(N14:R14) -> 24085310 | N14: 24085310 | T14: =SUM(U14:AA14) -> 19749630 | U14: 16606421 | V14: 335787.52 | W14: 792697.2 | X14: 671575.03 | Y14: =SUMIF('07.26'!$J$4:$J$1000,$F14,'07.26'!$M$4:$M$1000) -> 0 | Z14: =SUMIF('08.26'!$J$4:$J$1000,$F14,'08.26'!$M$4:$M$1000) -> 1343150.1 | AA14: =SUMIF('09.26'!$J$4:$J$1429,$F14,'09.26'!$M$4:$M$1429) -> 0 | AP14: Корпуса сдали/ закупаем заказчику бытовки еще через остатки в договоре
A15: Н | B15: 2 | C15: Кавказский б-р, вл. 51 | D15: ООО "ПИК-УК" | L15: =T15/M15 -> 0.91622931 | M15: =SUM(M16:M19) -> 44943646 | N15: =SUM(N16:N19) -> 32476099 | O15: =SUM(O16:O19) -> 0 | P15: =SUM(P16:P19) -> 0 | Q15: =SUM(Q16:Q19) -> 0 | R15: =SUM(R16:R19) -> 0 | S15: =SUM(S16:S19) -> 0 | T15: =SUM(U15:AA15) -> 41178686 | U15: =SUM(U16:U19) -> 36572446 | V15: =SUM(V16:V19) -> 2576090 | W15: =SUM(W16:W19) -> 340150 | X15: =SUM(X16:X19) -> 0 | Y15: =SUM(Y16:Y19) -> 600000 | Z15: =SUM(Z16:Z19) -> 1090000 | AA15: =SUM(AA16:AA19) -> 0 | AB15: =SUM(AB16:AB19) -> 0 | AD15: Бочаев Руслан Хасанович/ Ациев Абдулгалим Рабаданович
A16: Н | B16: 2.1 | C16: Площадка | E16: В процессе закрытия | F16: КБ51-СКЛ-ВДПР/пл от 28.10.2024 | G16: объекты капитального строительства, расположенные на земельном (-ых) участке (-ах) с кадастровым (-и) номером (-ами): 77:05:0005006:4958; 77:05:0005006:4954; 77:05:0005006:4953, по адресу: г. Москва, Кавказский б-р, вл. 51, площадка | H16: г. Москва, Кавказский б-р, вл. 51, площадка | I16: Электрика/водопровод | J16: 45551 | K16: 30.06.2026* | L16: =T16/M16 -> 0.73758616 | M16: =MAX(N16:R16) -> 2612967.7 | N16: 2612967.7 | T16: =SUM(U16:AA16) -> 1927288.8 | U16: 1927288.8 | Y16: =SUMIF('07.26'!$J$4:$J$1000,$F16,'07.26'!$M$4:$M$1000) -> 0 | Z16: =SUMIF('08.26'!$J$4:$J$1000,$F16,'08.26'!$M$4:$M$1000) -> 0 | AA16: =SUMIF('09.26'!$J$4:$J$1429,$F16,'09.26'!$M$4:$M$1429) -> 0
A17: Н | E17: Закрыт | F17: КБ51-Скала-РВР-МУС/эт2 от 01.10.2024 | G17: объект капитального строительства: корп. 1.5, 1.6, входящий в состав имущественного комплекса: «Общественно-жилая застройка, 1-я очередь строительства (корпуса 1.1, 1.2, 1.3, 1.4, 1.5, 1.6)» по адресу: Российская Федерация, город Москва, внутригородская территория муниципальный округ Царицыно, Кавказский бульвар, земельный участок 51 | H17: г. Москва, Кавказский б-р, вл. 51, 1-я оч., этап 2, корп. 1.5, 1.6 с подземным паркингом на 133 м/м | I17: Вывоз мусора | J17: 45537 | K17: 30.06.2026* | L17: =T17/M17 -> 1 | M17: =MAX(N17:R17) -> 893700 | N17: 893700 | P17: 893 700,00 | T17: =SUM(U17:AA17) -> 893700 | U17: 766200 | W17: 127500 | Y17: =SUMIF('07.26'!$J$4:$J$1000,$F17,'07.26'!$M$4:$M$1000) -> 0 | Z17: =SUMIF('08.26'!$J$4:$J$1000,$F17,'08.26'!$M$4:$M$1000) -> 0 | AA17: =SUMIF('09.26'!$J$4:$J$1429,$F17,'09.26'!$M$4:$M$1429) -> 0 | AP17: допник на согласовании
A18: Н | E18: В процессе закрытия | F18: КБ51-СКЛ-Моб/ДОО от 20.06.2023 | I18: Мобилизация | J18: 45139 | K18: 45900 | L18: =T18/M18 -> 0.74412307 | M18: 12034229 | T18: =SUM(U18:AA18) -> 8954947.1 | U18: 8742297.1 | W18: 212650 | Y18: =SUMIF('07.26'!$J$4:$J$1000,$F18,'07.26'!$M$4:$M$1000) -> 0 | Z18: =SUMIF('08.26'!$J$4:$J$1000,$F18,'08.26'!$M$4:$M$1000) -> 0 | AA18: =SUMIF('09.26'!$J$4:$J$1429,$F18,'09.26'!$M$4:$M$1429) -> 0
A19: Н | B19: 2.2 | C19: ДОО | E19: Подать на закрытие | F19: КБ51-СКЛ-Экс/ДОО от 20.06.2023 | G19: объект капитального строительства: «Дошкольная образовательная организация на 250 мест» по адресу: г. Москва, Кавказский б-р, вл. 51, ДОО на 250 мест, Этап 3.2 б | H19: г. Москва, Кавказский б-р, вл. 51, ДОО на 250 мест, Этап 3.2 б | I19: Эксплуатация | J19: 45870 | K19: 46173 | L19: =T19/M19 -> 1 | M19: 29402750 | N19: 28969432 | T19: =SUM(U19:AA19) -> 29402750 | U19: 25136660 | V19: 2576090 | Y19: =SUMIF('07.26'!$J$4:$J$1000,$F19,'07.26'!$M$4:$M$1000) -> 600000 | Z19: =SUMIF('08.26'!$J$4:$J$1000,$F19,'08.26'!$M$4:$M$1000) -> 1090000 | AA19: =SUMIF('09.26'!$J$4:$J$1429,$F19,'09.26'!$M$4:$M$1429) -> 0 | AP19: до мая
A20: Н | B20: 3 | C20: Матвеевский парк | D20: ООО "ПИК-УК" | L20: =T20/M20 -> 0.7547097 | M20: =SUM(M21:M34) -> 3.9690028e+08 | N20: =SUM(N21:N34) -> 3.4064068e+08 | O20: =SUM(O21:O34) -> 51161864 | P20: =SUM(P21:P34) -> 1.6126559e+08 | Q20: =SUM(Q21:Q34) -> 89921646 | R20: =SUM(R21:R34) -> 95922807 | S20: =SUM(S21:S34) -> 0 | T20: =SUM(T21:T34) -> 2.9954449e+08 | ... AB20: =SUM(AB21:AB34) -> 0 | AD20: Бочаев Руслан Хасанович/ Газзаев Алан Владимирович
A21: Н | B21: 3.1 | C21: Площадка | E21: Активный | F21: 021501717 от 05.05.2025 | G21: объекты капитального строительства, расположенные на земельном (-ых) участке (-ах) с кадастровым (-и) номером (-ами): 77:07:0012008:4324, по адресу: г. Москва, Очаковское ш., вл. 3, 3А, 5, площадка. | H21: г. Москва, Очаковское ш., вл. 3, 3А, 5, площадка | I21: Мобилизация | J21: 45768 | K21: 46326 | L21: =T21/M21 -> 0.63229391 | M21: =MAX(N21:R21) -> 32060692 | N21: 16837904 | Q21: 19805479 | R21: 32060692 | T21: =SUM(U21:AA21) -> 20271780 | U21: 9159594.4 | V21: 5763418.9 | W21: 1208634 | X21: 498320 | Y21: =SUMIF('07.26'!$J$4:$J$1000,$F21,'07.26'!$M$4:$M$1000) -> 2742907.3 | Z21: =SUMIF('08.26'!$J$4:$J$1000,$F21,'08.26'!$M$4:$M$1000) -> 0 | AA21: =SUMIF('09.26'!$J$4:$J$1429,$F21,'09.26'!$M$4:$M$1429) -> 898905.46
A22: Н | E22: Активный | F22: 022446936 от 23.10.2025 | G22: объекты капитального строительства, расположенные на земельном (-ых) участке (-ах) с кадастровым (-и) номером (-ами): 77:07:0012008:4341, 77:07:0012008:4403, 77:07:0012008:4413, 77:07:0012008:4342, по адресу: город Москва, вн.тер.г. муниципальный округ Очаково-Матвеевское, шоссе Очаковское, земельный участок 3А/32А. | H22: г. Москва, Очаковское ш., вл. 3, 3А, 5, площадка | I22: Электрика | J22: 45929 | K22: 46326 | L22: =T22/M22 -> 0.856058 | M22: =MAX(N22:R22) -> 1562091 | N22: 898226.71 | Q22: 1479646 | R22: 1562091 | T22: =SUM(U22:AA22) -> 1337240.5 | U22: 578276.21 | V22: 47550 | Y22: =SUMIF('07.26'!$J$4:$J$1000,$F22,'07.26'!$M$4:$M$1000) -> 628969.31 | Z22: =SUMIF('08.26'!$J$4:$J$1000,$F22,'08.26'!$M$4:$M$1000) -> 0 | AA22: =SUMIF('09.26'!$J$4:$J$1429,$F22,'09.26'!$M$4:$M$1429) -> 82444.95
A23: Н | B23: 3.2 | C23: Дороги между очередями | E23: Активный | F23: 021963258 от 29.07.2025 | G23: объекты капитального строительства, расположенные на земельном (-ых) участке (-ах) с кадастровым (-и) номером (-ами): 77:07:0012008:4340, 77:07:0012008:4342, 77:07:0012008:4323, 77:07:0012008:4403, 77:07:0012008:4409, 77:07:0012008:4417, 77:07:0012008:4406, по адресу: г. Москва, вн.тер.г. муниципальный округ Очаково- Матвеевское, шоссе Очаковское, земельный участок 3А/32А, земельный участок 5А/47 | H23: г. Москва, Очаковское ш., вл. 3, 3А, 5, площадка | I23: Эксплуатация | J23: 45809 | K23: 30.06.2026* | L23: =T23/M23 -> 0.83324976 | M23: =MAX(N23:R23) -> 81516997 | N23: 60552777 | P23: 81516997 | T23: =SUM(U23:AA23) -> 67924019 | U23: 29552777 | W23: 22387443 | X23: 3995949.6 | Y23: =SUMIF('07.26'!$J$4:$J$1000,$F23,'07.26'!$M$4:$M$1000) -> 3995949.6 | Z23: =SUMIF('08.26'!$J$4:$J$1000,$F23,'08.26'!$M$4:$M$1000) -> 3995949.6 | AA23: =SUMIF('09.26'!$J$4:$J$1429,$F23,'09.26'!$M$4:$M$1429) -> 3995949.6 | AP23: ДС продление 2026 / согласование
A24: Н | B24: 3.3 | C24: Бытовой городок | E24: Активный | F24: 021616823 от 23.05.2025 | G24: объекты капитального строительства, расположенные на земельном (-ых) участке (-ах) с кадастровым (-и) номером (-ами): 77:07:0012008:4402, по адресу: г. Москва, Очаковское ш., вл. 3, 3А, 5, площадка | H24: г. Москва, Очаковское ш., вл. 3, 3А, 5, площадка | I24: Эксплуатация | J24: 45778 | K24: 46387 | L24: =T24/M24 -> 0.84573538 | M24: =MAX(N24:R24) -> 32050456 | N24: 32050456 | T24: =SUM(U24:AA24) -> 27106204 | U24: 17791693 | V24: 1552418.5 | W24: 1552418.5 | X24: 1552418.5 | Y24: =SUMIF('07.26'!$J$4:$J$1000,$F24,'07.26'!$M$4:$M$1000) -> 1552418.5 | Z24: =SUMIF('08.26'!$J$4:$J$1000,$F24,'08.26'!$M$4:$M$1000) -> 1552418.5 | AA24: =SUMIF('09.26'!$J$4:$J$1429,$F24,'09.26'!$M$4:$M$1429) -> 1552418.5
A25: Н | B25: 3.4 | C25: Проектируемый проезд № 1439 | E25: Активный | F25: 023164846 от 11.03.2026 | G25: объекты капитального строительства, расположенные на земельном (-ых) участке (-ах) с кадастровым (-и) номером (-ами): 77:07:0012008:4398, по адресу: город Москва, внутригородская территория муниципальный округ Очаково-Матвеевское, проезд Стройкомбината, земельный участок 1А | H25: г. Москва, Очаковское ш., вл. 3, 3А, 5, площадка | I25: Эксплуатация | J25: 46082 | K25: 46326 | L25: =T25/M25 -> 0.87781357 | M25: =MAX(N25:R25) -> 9847079.1 | N25: 3609538.2 | Q25: 9847079.1 | T25: =SUM(U25:AA25) -> 8643899.7 | U25: 1424823.2 | V25: 1203179.4 | W25: 1203179.4 | X25: 1203179.4 | Y25: =SUMIF('07.26'!$J$4:$J$1000,$F25,'07.26'!$M$4:$M$1000) -> 1203179.4 | Z25: =SUMIF('08.26'!$J$4:$J$1000,$F25,'08.26'!$M$4:$M$1000) -> 1203179.4 | AA25: =SUMIF('09.26'!$J$4:$J$1429,$F25,'09.26'!$M$4:$M$1429) -> 1203179.4
A26: Н | B26: 3.5 | C26: 4 очередь | E26: Активный | F26: 019968493 от 03.09.2024 | G26: объекты капитального строительства, расположенные на земельном (-ых) участке (-ах) с кадастровым (-и) номером (-ами): 77:07:0012008:4100; 77:07:0012008:4101; 77:07:0012008:4083; 77:07:0012008:4075; 77:07:0012008:4096; 77:07:0012008:4097; 77:07:0012008:4077; 77:07:0012008:4095; 77:07:0012008:4091; 77:07:0012008:4081; 77:07:0012008:3750; 77:07:0012008:4094; 77:07:0012008:4084; 77:07:0012008:4079, по адресу: г. Москва, Очаковское ш., вл. 3, 3а, 5, площадка | H26: г. Москва, Очаковское ш., вл. 3, 3А, 5, площадка | I26: Эксплуатация | J26: 45474 | K26: 46387 | L26: =T26/M26 -> 0.89107712 | M26: =MAX(N26:R26) -> 63374747 | N26: 63374747 | P26: 63374747 | T26: =SUM(U26:AA26) -> 56471787 | U26: 19781197 | W26: 27366741 | X26: 1747994.2 | Y26: =SUMIF('07.26'!$J$4:$J$1000,$F26,'07.26'!$M$4:$M$1000) -> 2797454.2 | Z26: =SUMIF('08.26'!$J$4:$J$1000,$F26,'08.26'!$M$4:$M$1000) -> 2389200.2 | AA26: =SUMIF('09.26'!$J$4:$J$1429,$F26,'09.26'!$M$4:$M$1429) -> 2389200.2 | AP26: Продление
A27: Н | E27: Активный | F27: 019346722 от 30.05.2024 | G27: объекты капитального строительства, расположенные на земельном (-ых) участке (-ах) с кадастровым (-и) номером (-ами): 77:07:0012008:4402, по адресу: г. Москва, Очаковское ш., вл. 3, 3а, 5, площадка | H27: г. Москва, Очаковское ш., вл. 3, 3А, 5, площадка | I27: Мобилизация | J27: 45404 | K27: 46326 | L27: =T27/M27 -> 0.75280105 | M27: =MAX(N27:R27) -> 53251243 | N27: 48885480 | O27: 51161864 | Q27: 52551153 | R27: 53251243 | T27: =SUM(U27:AA27) -> 40087592 | U27: 33934562 | V27: 848148.69 | W27: 779785.49 | X27: 1182655.1 | Y27: =SUMIF('07.26'!$J$4:$J$1000,$F27,'07.26'!$M$4:$M$1000) -> 1117361.2 | Z27: =SUMIF('08.26'!$J$4:$J$1000,$F27,'08.26'!$M$4:$M$1000) -> 321075 | AA27: =SUMIF('09.26'!$J$4:$J$1429,$F27,'09.26'!$M$4:$M$1429) -> 1904004.4
A28: Н | E28: Активный | F28: 020226119 от 10.10.2024 | G28: объекты капитального строительства, расположенные на земельном (-ых) участке (-ах) с кадастровым (-и) номером (-ами): 77:07:0012008:4402, по адресу: Очаковское ш., вл. 3, 3А, 5, площадка | H28: г. Москва, Очаковское ш., вл. 3, 3А, 5, площадка | I28: Электрика | J28: 45537 | K28: 46234 | L28: =T28/M28 -> 0.94585424 | M28: =MAX(N28:R28) -> 6238289.6 | N28: 6133744.2 | Q28: 6238289.6 | T28: =SUM(U28:AA28) -> 5900512.7 | U28: 5399130.1 | V28: 396837.13 | Y28: =SUMIF('07.26'!$J$4:$J$1000,$F28,'07.26'!$M$4:$M$1000) -> 104545.45 | Z28: =SUMIF('08.26'!$J$4:$J$1000,$F28,'08.26'!$M$4:$M$1000) -> 0 | AA28: =SUMIF('09.26'!$J$4:$J$1429,$F28,'09.26'!$M$4:$M$1429) -> 0
A29: Н | B29: 3.6 | C29: ЖК Среда | E29: В процессе закрытия | F29: 018419783 от 25.12.2023 | G29: объекты капитального строительства, расположенные на земельном (-ых) участке (-ах) с кадастровым (-и) номером (-ами): -, по адресу: г. Москва, Очаковское ш., вл. 3, 3А, 5. | H29: г. Москва, Очаковское ш., вл. 3, 3А, 5, площадка | I29: Эксплуатация | J29: 45292 | L29: =T29/M29 -> 0.64792997 | M29: =MAX(N29:R29) -> 27959055 | N29: 27959055 | T29: =SUM(U29:AA29) -> 18115510 | U29: 18115510 | Y29: =SUMIF('07.26'!$J$4:$J$1000,$F29,'07.26'!$M$4:$M$1000) -> 0 | Z29: =SUMIF('08.26'!$J$4:$J$1000,$F29,'08.26'!$M$4:$M$1000) -> 0 | AA29: =SUMIF('09.26'!$J$4:$J$1429,$F29,'09.26'!$M$4:$M$1429) -> 0 | AP29: Продлен новым договором/ по факту все закрыто/ были ПМК, которые не обслуживали и КЛ/вода , также вышли в марте, июнь-июль 2024 простой, поэтому 4 месяца в остатке
A30: Н | E30: Активный | F30: 023532811 от 14.05.2026 | H30: г. Москва, Очаковское ш., вл. 3, 3А, 5, Площадка (Среда) | I30: Эксплуатация | J30: 46023 | K30: 46387 | L30: =T30/M30 -> 0.73932572 | M30: =MAX(N30:R30) -> 10082510 | N30: 10082510 | P30: 10082510 | T30: =SUM(U30:AA30) -> 7454258.7 | U30: 0 | W30: 4332585.5 | X30: 780418.3 | Y30: =SUMIF('07.26'!$J$4:$J$1000,$F30,'07.26'!$M$4:$M$1000) -> 780418.3 | Z30: =SUMIF('08.26'!$J$4:$J$1000,$F30,'08.26'!$M$4:$M$1000) -> 780418.3 | AA30: =SUMIF('09.26'!$J$4:$J$1429,$F30,'09.26'!$M$4:$M$1429) -> 780418.3 | AP30: смена адреса/продление/согласование договора
A31: Н | E31: Активный | F31: СК-МОБ/ОЧШ-5.1-5.8 от 14.03.2024 | G31: объекты капитального строительства, расположенные на земельном (-ых) участке (-ах) с кадастровым (-и) номером (-ами): 77:07:0012008:4413, по адресу: г. Москва, Очаковское ш., вл. 3, 3а, 5 | H31: г. Москва, Очаковское ш., вл. 3, 3А, 5, площадка | I31: Мобилизация | J31: 45292 | K31: 30.06.2026* | L31: =T31/M31 -> 0.91232223 | M31: =MAX(N31:R31) -> 44924741 | N31: 44924741 | T31: =SUM(U31:AA31) -> 40985840 | U31: 40906831 | V31: 79009 | Y31: =SUMIF('07.26'!$J$4:$J$1000,$F31,'07.26'!$M$4:$M$1000) -> 0 | Z31: =SUMIF('08.26'!$J$4:$J$1000,$F31,'08.26'!$M$4:$M$1000) -> 0 | AA31: =SUMIF('09.26'!$J$4:$J$1429,$F31,'09.26'!$M$4:$M$1429) -> 0 | AP31: новые объемы по новому договору, остатки добираются по этому
A32: Н | E32: Активный | F32: 023392699 от 17.04.2026 | G32: объекты капитального строительства, расположенные на земельном (-ых) участке (-ах) с кадастровым (-и) номером (-ами): 77:07:0012008:4413, по адресу: г. Москва, ЗАО, Очаково-Матвеевское, Очаковское ш. | H32: г. Москва, Очаковское ш., вл. 3, 3А, 5, Площадка (Среда) | I32: Мобилизация | J32: 46108 | K32: 46173 | L32: =T32/M32 -> 0.612414 | M32: =MAX(N32:R32) -> 7656436.2 | N32: 347902.46 | P32: 6291340.3 | R32: 7656436.2 | T32: =SUM(U32:AA32) -> 4688908.7 | U32: 0 | V32: 347902.46 | W32: 1026357.6 | Y32: =SUMIF('07.26'!$J$4:$J$1000,$F32,'07.26'!$M$4:$M$1000) -> 2370928.2 | Z32: =SUMIF('08.26'!$J$4:$J$1000,$F32,'08.26'!$M$4:$M$1000) -> 0 | AA32: =SUMIF('09.26'!$J$4:$J$1429,$F32,'09.26'!$M$4:$M$1429) -> 943720.46 | AP32: смена адреса/ на подписании
A33: Н | B33: 3.7 | C33: ЖК Комфорт | E33: В процессе закрытия | F33: 022769562 от 12.12.2025 | G33: объекты капитального строительства, расположенные на земельном (-ых) участке (-ах) с кадастровым (-и) номером (-ами): 77:07:0012008:4421, по адресу: г. Москва, Очаковское ш., вл. 3, 3а, 5 | H33: г. Москва, Очаковское ш., вл. 3, 3А, 5, Площадка (Среда) | I33: Мобилизация | J33: 46002 | K33: 46173 | L33: =T33/M33 -> 0 | M33: =MAX(N33:R33) -> 24983595 | N33: 24983595 | T33: =SUM(U33:AA33) -> 0 | U33: 0 | Y33: =SUMIF('07.26'!$J$4:$J$1000,$F33,'07.26'!$M$4:$M$1000) -> 0 | Z33: =SUMIF('08.26'!$J$4:$J$1000,$F33,'08.26'!$M$4:$M$1000) -> 0 | AA33: =SUMIF('09.26'!$J$4:$J$1429,$F33,'09.26'!$M$4:$M$1429) -> 0 | AP33: Не начали работы , будет еще экспл.
A34: Н | B34: 3.8 | C34: Бытовой городок (без дорог) | E34: Активный | F34: 024196291 от 07.09.2026 | G34: объект капитального строительства: объекты капитального строительства, расположенные на земельном (-ых) участке (-ах) с кадастровым (-и) номером (-ами): 77:07:0012008:4421, по адресу: г. Москва, Очаковское ш., вл. 3, 3А, 5, Очередь (Стандарт) | H34: г. Москва, Очаковское ш., вл. 3, 3А, 5, Очередь (Стандарт) | I34: Эксплуатация | J34: 46235 | K34: 46387 | L34: =T34/M34 -> 0.4 | M34: =MAX(N34:R34) -> 1392344.9 | R34: 1392344.9 | T34: =SUM(U34:AA34) -> 556937.98 | U34: 0 | Y34: =SUMIF('07.26'!$J$4:$J$1000,$F34,'07.26'!$M$4:$M$1000) -> 0 | Z34: =SUMIF('08.26'!$J$4:$J$1000,$F34,'08.26'!$M$4:$M$1000) -> 0 | AA34: =SUMIF('09.26'!$J$4:$J$1429,$F34,'09.26'!$M$4:$M$1429) -> 556937.98
A35: Н | B35: 4 | C35: Моментс | D35: ООО "ПИК-УК" | L35: =T35/M35 -> 0.96556171 | M35: =SUM(M36) -> 50777794 | N35: =SUM(N36) -> 47432904 | O35: =SUM(O36) -> 0 | P35: =SUM(P36) -> 0 | Q35: =SUM(Q36) -> 50777794 | R35: =SUM(R36) -> 0 | S35: =SUM(S36) -> 0 | T35: =SUM(U35:AA35) -> 49029094 | U35: =SUM(U36) -> 45684204 | V35: =SUM(V36) -> 0 | W35: =SUM(W36) -> 0 | X35: =SUM(X36) -> 0 | Y35: =SUM(Y36) -> 3344890 | Z35: =SUM(Z36) -> 0 | AA35: =SUM(AA36) -> 0 | AB35: =SUM(AB36) -> 0 | AD35: Алиев Абдулагат Алиевич/ Чалишев Фируз Талбакович
A36: Н | B36: 4.1 | C36: Площадка | E36: Подать на закрытие | F36: СК/ВЛ-СДП от 01.03.2023 | G36: объекты капитального строительства, расположенные на земельном (-ых) участке (-ах) с кадастровым (-и) номером (-ами): 77:08:0009002:1000, по адресу: г. Москва, Волоколамское ш., вл. 28, площадка. | H36: г. Москва, Волоколамское ш., вл. 28, площадка | I36: Эксплуатация | J36: 44986 | K36: 46173 | L36: =T36/M36 -> 0.96556171 | M36: =MAX(N36:R36) -> 50777794 | N36: 47432904 | Q36: 50777794 | T36: =SUM(U36:AA36) -> 49029094 | U36: 45684204 | Y36: =SUMIF('07.26'!$J$4:$J$1000,$F36,'07.26'!$M$4:$M$1000) -> 3344890 | Z36: =SUMIF('08.26'!$J$4:$J$1000,$F36,'08.26'!$M$4:$M$1000) -> 0 | AA36: =SUMIF('09.26'!$J$4:$J$1429,$F36,'09.26'!$M$4:$M$1429) -> 0 | AP36: Только эксплуатация
A37: Н | B37: 5 | C37: Саларьево парк | D37: ООО "ПИК-МЕНЕДЖМЕНТ" | L37: =T37/M37 -> 0.74289462 | M37: =SUM(M38:M53) -> 271974971 | N37: =SUM(N38:N53) -> 2.2894123e+08 | O37: =SUM(O38:O53) -> 55222907 | P37: =SUM(P38:P53) -> 17453540 | Q37: =SUM(Q38:Q53) -> 0 | R37: =SUM(R38:R53) -> 1.0332768e+08 | S37: =SUM(S38:S53) -> 0 | T37: =SUM(T38:T53) -> 2.0204874e+08 | ... AB37: =SUM(AB38:AB53) -> 0 | AD37: Петропавловских Александр Павлович/-
A38: Н | B38: 5.1 | C38: 83 корпус | E38: Активный | F38: 020545364 от 26.11.2024 | G38: объект капитального строительства: «Многоэтажный жилой дом, корпус 83 с подземной стоянкой автомобилей, с инженерными сетями, в составе Жилой застройки с объектами социальной инфраструктуры» по адресу: Москва, НАО, вн.тер.г. поселение, г. Москва, Московский, улица Саларьевская, земельный участок 17 | H38: д. Саларьево, 14- очередь, корпус 83 | I38: Мобилизация | J38: 45573 | K38: 46326 | L38: =T38/M38 -> 0.98687516 | M38: =MAX(N38:R38) -> 27115820 | N38: 25161404 | O38: 25582776 | R38: 27115820 | T38: =SUM(U38:AA38) -> 26759929 | U38: 23058124 | W38: 1751918.6 | Y38: =SUMIF('07.26'!$J$4:$J$1000,$F38,'07.26'!$M$4:$M$1000) -> 430432 | Z38: =SUMIF('08.26'!$J$4:$J$1000,$F38,'08.26'!$M$4:$M$1000) -> 1519453.9 | AA38: =SUMIF('09.26'!$J$4:$J$1429,$F38,'09.26'!$M$4:$M$1429) -> 0
A39: Н | E39: Активный | F39: 021299329 от 24.03.2025 | G39: объект капитального строительства: «Многоэтажный жилой дом, корпус 83 с подземной стоянкой автомобилей, с инженерными сетями, в составе Жилой застройки с объектами социальной инфраструктуры» по адресу: Москва, НАО, вн.тер.г. поселение, г. Москва, Московский, улица Саларьевская, земельный участок 17 | H39: д. Саларьево, 14 очередь, корп. 83 | I39: Эксплуатация | J39: 46023 | K39: 46387 | L39: =T39/M39 -> 0.86480855 | M39: =MAX(N39:R39) -> 30729117 | N39: 30729117 | T39: =SUM(U39:AA39) -> 26574803 | U39: 18430204 | V39: 1357433.2 | W39: 1357433.2 | X39: 1357433.2 | Y39: =SUMIF('07.26'!$J$4:$J$1000,$F39,'07.26'!$M$4:$M$1000) -> 1357433.2 | Z39: =SUMIF('08.26'!$J$4:$J$1000,$F39,'08.26'!$M$4:$M$1000) -> 1357433.2 | AA39: =SUMIF('09.26'!$J$4:$J$1429,$F39,'09.26'!$M$4:$M$1429) -> 1357433.2
A40: Н | B40: 5.2 | C40: 74 корпус | E40: Активный | F40: 022039867 от 11.08.2025 | G40: объекты капитального строительства, расположенные на земельном (-ых) участке (-ах) с кадастровым (-и) номером (-ами): 77:17:0110205:17424, 77:17:0110205:17418, 77:17:0110205:17420, по адресу: г. Москва, п. Московский, д. Саларьево | H40: д. Саларьево, 13 очередь | I40: Мобилизация | J40: 45819 | K40: 46326 | L40: =T40/M40 -> 0.50003551 | M40: =MAX(N40:R40) -> 14665025 | N40: 14060669 | R40: 14665025 | T40: =SUM(U40:AA40) -> 7333033.4 | U40: 2491884.8 | V40: 923026.17 | W40: 2729875.9 | X40: 417568.11 | Y40: =SUMIF('07.26'!$J$4:$J$1000,$F40,'07.26'!$M$4:$M$1000) -> 136719.09 | Z40: =SUMIF('08.26'!$J$4:$J$1000,$F40,'08.26'!$M$4:$M$1000) -> 589137.52 | AA40: =SUMIF('09.26'!$J$4:$J$1429,$F40,'09.26'!$M$4:$M$1429) -> 44821.8 | AP40: вышел ДС
...

Sheet Распределение объектов  (копия)
A1: РЕЕСТР ДЕЙСТВУЮЩИХ КОНТРАКТОВ ООО "СКАЛА"
A2: Актуальная инфомация на 25.05.2026
A3: № п/п | B3: Объекты Адрес/корпус/очередь | C3: Заказчик | D3: Договор | E3: Объект и адрес по договору | F3: Адрес ПИК | G3: Вид работ | H3: ГПР | I3: Сумма договора, руб | J3: Сумма договора, руб на 21.04.2026 | K3: ПДЦ 21.04.2026 - 04.05.2026 | L3: ПДЦ 04.05.2026 - 12.05.2026 | M3: ПДЦ 12.05.2026 - 18.05.2026 | Q3: Шаблон | R3: Выполнено, руб | S3: Актуально на 21.04.2026 | T3: Выполнение апрель | U3: Выполнение май | X3: Шаблон | Y3: РП/Прораб | Z3: Примечания
A4: Общая стоимость контрактов, руб. | I4: =I6+I132 -> 3136447679 | J4: =J6+J132 -> 3100521350 | K4: =K6+K132 -> 1.3500912e+08 | L4: =L6+L132 -> 86949271 | M4: =M6+M132 -> 0 | N4: =N6+N132 -> 0 | O4: =O6+O132 -> 0 | P4: =P6+P132 -> 0 | Q4: =Q6+Q132 -> 0 | R4: =SUM(S4:W4) -> 1724587856 | S4: =S6+S132 -> 1595813591 | T4: =T6+T132 -> 1.2429582e+08 | U4: =U6+U132 -> 4478449.4 | V4: =V6+V132 -> 0 | W4: =W6+W132 -> 0 | X4: =X6+X132 -> 0
A5: ЗАКАЗЧИК ПИК
A6: Общая стоимость по Заказчику ПИК, руб. | I6: =I7+I13+I17+I31+I33+I47+I66+I70+I73+I87+I90+I92+I95+I98+I101+I105+I108+I123+I125+I44+I113+I128 -> 2288055419 | J6: =J7+J13+J17+J31+J33+J47+J66+J70+J73+J87+J90+J92+J95+J98+J101+J105+J108+J123+J125+J44+J113+J128 -> 2253826639 | K6: =K7+K13+K17+K31+K33+K47+K66+K70+K73+K87+K90+K92+K95+K98+K101+K105+K108+K123+K125+K44+K113+K128 -> 1.3500912e+08 | L6: =L7+L13+L17+L31+L33+L47+L66+L70+L73+L87+L90+L92+L95+L98+L101+L105+L108+L123+L125+L44+L113+L128 -> 86949271 | M6: =M7+M13+M17+M31+M33+M47+M66+M70+M73+M87+M90+M92+M95+M98+M101+M105+M108+M123+M125+M44+M113+M128 -> 0 | N6: =N7+N13+N17+N31+N33+N47+N66+N70+N73+N87+N90+N92+N95+N98+N101+N105+N108+N123+N125+N44+N113+N128 -> 0 | O6: =O7+O13+O17+O31+O33+O47+O66+O70+O73+O87+O90+O92+O95+O98+O101+O105+O108+O123+O125+O44+O113+O128 -> 0 | P6: =P7+P13+P17+P31+P33+P47+P66+P70+P73+P87+P90+P92+P95+P98+P101+P105+P108+P123+P125+P44+P113+P128 -> 0 | Q6: =Q7+Q13+Q17+Q31+Q33+Q47+Q66+Q70+Q73+Q87+Q90+Q92+Q95+Q98+Q101+Q105+Q108+Q123+Q125+Q44+Q113+Q128 -> 0 | R6: =SUM(S6:W6) -> 1392282773 | S6: =S7+S13+S17+S31+S33+S47+S66+S70+S73+S87+S90+S92+S95+S98+S101+S105+S108+S123+S125+S44+S113+S128 -> 1279320369 | T6: =T7+T13+T17+T31+T33+T47+T66+T70+T73+T87+T90+T92+T95+T98+T101+T105+T108+T123+T125+T44+T113+T128 -> 108483955 | U6: =U7+U13+U17+U31+U33+U47+U66+U70+U73+U87+U90+U92+U95+U98+U101+U105+U108+U123+U125+U44+U113+U128 -> 4478449.4 | V6: =V7+V13+V17+V31+V33+V47+V66+V70+V73+V87+V90+V92+V95+V98+V101+V105+V108+V123+V125+V44+V113+V128 -> 0 | W6: =W7+W13+W17+W31+W33+W47+W66+W70+W73+W87+W90+W92+W95+W98+W101+W105+W108+W123+W125+W44+W113+W128 -> 0 | X6: =X7+X13+X17+X31+X33+X47+X66+X70+X73+X87+X90+X92+X95+X98+X101+X105+X108+X123+X125+X44+X113+X128 -> 0
A7: 1 | B7: Волжский парк (1-й Грайвороновский) | C7: ООО "ПИК-МЕНЕДЖМЕНТ" | I7: =SUM(I8:I12) -> 78450355 | J7: =SUM(J8:J12) -> 78450355 | K7: =SUM(K8:K12) -> 0 | L7: =SUM(L8:L12) -> 0 | M7: =SUM(M8:M12) -> 0 | N7: =SUM(N8:N12) -> 0 | O7: =SUM(O8:O12) -> 0 | P7: =SUM(P8:P12) -> 0 | Q7: =SUM(Q8:Q12) -> 0 | R7: =SUM(S7:W7) -> 62463523 | S7: =SUM(S8:S12) -> 48808767 | T7: =SUM(T8:T12) -> 9176306.6 | U7: =SUM(U8:U12) -> 4478449.4 | V7: =SUM(V8:V12) -> 0 | W7: =SUM(W8:W12) -> 0 | X7: =SUM(X8:X12) -> 0 | Y7: Бочаев Руслан Хасанович/ -
A8: 1.1 | B8: Корпус 6 | D8: №ВП6.2-СКАЛА-МР от 16.12.2024 | E8: «Жилые дома Корпуса 6.1, 6.2. Этап 2. Корпус 6.2» по адресу: Москва, ЮВАО, Текстильщики, у-й Грайвороновский проезд, вл.3 | F8: г. Москва, 1-й Грайвороновский пр-д, вл. 3, 6-ой очереди | G8: Мобилизация | H8: 15.11.2024 -30.06.2026* | I8: =MAX(J8:P8) -> 19044343 | J8: 19044343 | R8: =SUM(S8:W8) -> 12136393 | S8: 6367680.4 | T8: 2082960 | U8: 3685752.2
D9: №ВП6.2-СКАЛА-СПС от 11.12.2024 | E9: «Жилые дома Корпуса 6.1, 6.2. Этап 2. Корпус 6.2» по адресу: Москва, ЮВАО, Текстильщики, у-й Грайвороновский проезд, вл.3 | F9: г. Москва, 1-й Грайвороновский пр-д, вл. 3, корп. 6.1, 6.2 | G9: Эксплуатация | H9: 01.01.2026 -31.03.2026 | I9: =MAX(J9:P9) -> 29591768 | J9: 29591768 | R9: =SUM(S9:W9) -> 31349327 | S9: 24591768 | T9: 6757559.1 | Z9: НЗ на продление на подписании
A10: 1.2 | B10: Площадка | D10: №ВП-СКАЛА-ВЖББ-ПЛОЩ от 04.08.2025 | E10: объекты капитального строительства, расположенные на земельном (-ых) участке (-ах) с кадастровым (-и) номером (-ами): 77:04:0002005, по адресу: г. Москва, 1-й Грайвороновский пр-д, вл. 3, площадка | F10: г. Москва, 1-й Грайвороновский пр-д, вл. 3, площадка | G10: Мобилизация | H10: 12.05.2025 -31.12.2026 | I10: =MAX(J10:P10) -> 1292350.9 | J10: 1292350.9 | R10: =SUM(S10:W10) -> 1242897.7 | S10: 1242897.7 | Z10: пока на стопе, но в будущем работы планируются на площадке
D11: №ВП-СКАЛА-ЭКСП от 17.04.2026 | E11: объекты капитального строительства, расположенные на земельном (-ых) участке (-ах) с кадастровым (-и) номером (-ами): 77:04:0002005:16049, по адресу: г. Москва, 1-й Грайвороновский пр-д, вл. 3, площадка | F11: г. Москва, 1-й Грайвороновский пр-д, вл. 3, площадка | G11: Эксплуатация | H11: 01.01.2026 -31.03.2026 | I11: =MAX(J11:P11) -> 4436583.1 | J11: 4436583.1 | R11: =SUM(S11:W11) -> 0 | S11: 0 | Z11: подписали 21.04.2026, полностью забираем апрель
A12: 1.3 | B12: Корпус 5 | D12: №В5-СП-СК от 06.10.2022 | E12: объект капитального строительства,предполагаемый к размещению на земельном (-ых) участке (-ах) с кадастровым (-и) номером (- ами): 77:04:0002005:10954, по адресу: г. Москва, 1-й Грайвороновский пр., вл. 3 (корп. 5.1, 5.2, 5.3, 5.4) | F12: г. Москва, 1-й Грайвороновский пр-д, вл. 3, общедомовой к корп. 5.1-5.4 | G12: Мобилизация | H12: 01.09.2022 -31.12.2026 | I12: =MAX(J12:P12) -> 24085310 | J12: 24085310 | R12: =SUM(S12:W12) -> 17734905 | S12: 16606421 | T12: 335787.52 | U12: 792697.2 | Z12: Корпуса сдали/ закупаем заказчику бытовки еще через остатки в договоре
A13: 2 | B13: Кавказский бульвар | C13: ООО "ПИК-УК" | I13: =SUM(I14:I16) -> 32508599 | J13: =SUM(J14:J16) -> 32508599 | K13: =SUM(K14:K16) -> 0 | L13: =SUM(L14:L16) -> 0 | M13: =SUM(M14:M16) -> 0 | N13: =SUM(N14:N16) -> 0 | O13: =SUM(O14:O16) -> 0 | P13: =SUM(P14:P16) -> 0 | Q13: =SUM(Q14:Q16) -> 0 | R13: =SUM(S13:W13) -> 32724256 | S13: =SUM(S14:S16) -> 30148166 | T13: =SUM(T14:T16) -> 2576090 | U13: =SUM(U14:U16) -> 0 | V13: =SUM(V14:V16) -> 0 | W13: =SUM(W14:W16) -> 0 | X13: =SUM(X14:X16) -> 0 | Y13: Бочаев Руслан Хасанович/ Ациев Абдулгалим Рабаданович
A14: 2.1 | B14: Площадка | D14: №КБ51-СКЛ-ВДПР/пл от 28.10.2024 | E14: объекты капитального строительства, расположенные на земельном (-ых) участке (-ах) с кадастровым (-и) номером (-ами): 77:05:0005006:4958; 77:05:0005006:4954; 77:05:0005006:4953, по адресу: г. Москва, Кавказский б-р, вл. 51, площадка | F14: г. Москва, Кавказский б-р, вл. 51, площадка | G14: Электрика/водопровод | H14: 16.09.2024 -30.06.2026* | I14: =MAX(J14:P14) -> 2612967.7 | J14: 2612967.7 | R14: =SUM(S14:W14) -> 1927288.8 | S14: 1927288.8
D15: №КБ51-Скала-РВР-МУС/эт2 от 01.10.2024 | E15: объект капитального строительства: корп. 1.5, 1.6, входящий в состав имущественного комплекса: «Общественно-жилая застройка, 1-я очередь строительства (корпуса 1.1, 1.2, 1.3, 1.4, 1.5, 1.6)» по адресу: Российская Федерация, город Москва, внутригородская территория муниципальный округ Царицыно, Кавказский бульвар, земельный участок 51 | F15: г. Москва, Кавказский б-р, вл. 51, 1-я оч., этап 2, корп. 1.5, 1.6 с подземным паркингом на 133 м/м | G15: Вывоз мусора | H15: 02.09.2024 -30.06.2026* | I15: =MAX(J15:P15) -> 926200 | J15: =766200+160000 -> 926200 | R15: =SUM(S15:W15) -> 766200 | S15: 766200 | Z15: допник на согласовании
A16: 2.2 | B16: ДОО | D16: №КБ51-СКЛ-Экс/ДОО от 20.06.2023 | E16: объект капитального строительства: «Дошкольная образовательная организация на 250 мест» по адресу: г. Москва, Кавказский б-р, вл. 51, ДОО на 250 мест, Этап 3.2 б | F16: г. Москва, Кавказский б-р, вл. 51, ДОО на 250 мест, Этап 3.2 б | G16: Эксплуатация | H16: 01.08.2025 - 31.05.2026 | I16: =MAX(J16:P16) -> 28969432 | J16: 28969432 | R16: =SUM(S16:W16) -> 30030768 | S16: 27454678 | T16: 2576090 | Z16: до мая
A17: 3 | B17: Матвеевский парк ( Vangarden, Среда на Лобачевского) | C17: ООО "ПИК-УК" | I17: =SUM(I18:I30) -> 3.6772852e+08 | J17: =SUM(J18:J30) -> 3.4448791e+08 | K17: =SUM(K18:K30) -> 51161864 | L17: =SUM(L18:L30) -> 81516997 | M17: =SUM(M18:M30) -> 0 | N17: =SUM(N18:N30) -> 0 | O17: =SUM(O18:O30) -> 0 | P17: =SUM(P18:P30) -> 0 | Q17: =SUM(Q18:Q30) -> 0 | R17: =SUM(S17:W17) -> 1.8688286e+08 | S17: =SUM(S18:S30) -> 1.7664439e+08 | T17: =SUM(T18:T30) -> 10238464 | U17: =SUM(U18:U30) -> 0 | V17: =SUM(V18:V30) -> 0 | W17: =SUM(W18:W30) -> 0 | X17: =SUM(X18:X30) -> 0 | Y17: Петропавловских Александр Павлович/ Газзаев Алан Владимирович
A18: 3.1 | B18: Площадка | D18: № 021501717 от 05.05.2025 года | E18: объекты капитального строительства, расположенные на земельном (-ых) участке (-ах) с кадастровым (-и) номером (-ами): 77:07:0012008:4324, по адресу: г. Москва, Очаковское ш., вл. 3, 3А, 5, площадка. | F18: г. Москва, Очаковское ш., вл. 3, 3А, 5, площадка | G18: Мобилизация | H18: 21.04.2025 - 31.05.2026 | I18: =MAX(J18:P18) -> 16837904 | J18: 16837904 | R18: =SUM(S18:W18) -> 14923013 | S18: 9159594.4 | T18: 5763418.9
D19: № 022446936 от 23.10.2025 года | E19: объекты капитального строительства, расположенные на земельном (-ых) участке (-ах) с кадастровым (-и) номером (-ами): 77:07:0012008:4341, 77:07:0012008:4403, 77:07:0012008:4413, 77:07:0012008:4342, по адресу: город Москва, вн.тер.г. муниципальный округ Очаково-Матвеевское, шоссе Очаковское, земельный участок 3А/32А. | F19: г. Москва, Очаковское ш., вл. 3, 3А, 5, площадка | G19: Электрика | H19: 29.09.2025 - 31.01.2026 | I19: =MAX(J19:P19) -> 898226.71 | J19: 898226.71 | R19: =SUM(S19:W19) -> 625826.21 | S19: 578276.21 | T19: 47550
A20: 3.2 | B20: Дороги между очередями | D20: №021963258 от 29.07.2025 | E20: объекты капитального строительства, расположенные на земельном (-ых) участке (-ах) с кадастровым (-и) номером (-ами): 77:07:0012008:4340, 77:07:0012008:4342, 77:07:0012008:4323, 77:07:0012008:4403, 77:07:0012008:4409, 77:07:0012008:4417, 77:07:0012008:4406, по адресу: г. Москва, вн.тер.г. муниципальный округ Очаково- Матвеевское, шоссе Очаковское, земельный участок 3А/32А, земельный участок 5А/47 | F20: г. Москва, Очаковское ш., вл. 3, 3А, 5, площадка | G20: Эксплуатация | H20: 01.06.2025 -30.06.2026* | I20: =MAX(J20:P20) -> 81516997 | J20: 60552777 | L20: 81516997 | R20: =SUM(S20:W20) -> 29552777 | S20: 29552777 | Z20: ДС продление 2026 / согласование
A21: 3.3 | B21: Бытовой городок | D21: № 021616823 от 23.05.2025 года | E21: объекты капитального строительства, расположенные на земельном (-ых) участке (-ах) с кадастровым (-и) номером (-ами): 77:07:0012008:4402, по адресу: г. Москва, Очаковское ш., вл. 3, 3А, 5, площадка | F21: г. Москва, Очаковское ш., вл. 3, 3А, 5, площадка | G21: Эксплуатация | H21: 01.05.2025 - 31.12.2026 | I21: =MAX(J21:P21) -> 32050456 | J21: 32050456 | R21: =SUM(S21:W21) -> 19344112 | S21: 17791693 | T21: 1552418.5
A22: 3.4 | B22: Проектируемый проезд № 1439 | D22: № 023164846 от 11.03.2026 года | E22: объекты капитального строительства, расположенные на земельном (-ых) участке (-ах) с кадастровым (-и) номером (-ами): 77:07:0012008:4398, по адресу: город Москва, внутригородская территория муниципальный округ Очаково-Матвеевское, проезд Стройкомбината, земельный участок 1А | F22: г. Москва, Очаковское ш., вл. 3, 3А, 5, площадка | G22: Эксплуатация | H22: 01.03.2026 - 30.06.2026 | I22: =MAX(J22:P22) -> 3609538.2 | J22: 3609538.2 | R22: =SUM(S22:W22) -> 2628002.6 | S22: 1424823.2 | T22: 1203179.4
A23: 3.5 | B23: 4 очередь | D23: №019968493 от 03.09.2024 | E23: объекты капитального строительства, расположенные на земельном (-ых) участке (-ах) с кадастровым (-и) номером (-ами): 77:07:0012008:4100; 77:07:0012008:4101; 77:07:0012008:4083; 77:07:0012008:4075; 77:07:0012008:4096; 77:07:0012008:4097; 77:07:0012008:4077; 77:07:0012008:4095; 77:07:0012008:4091; 77:07:0012008:4081; 77:07:0012008:3750; 77:07:0012008:4094; 77:07:0012008:4084; 77:07:0012008:4079, по адресу: г. Москва, Очаковское ш., вл. 3, 3а, 5, площадка | F23: г. Москва, Очаковское ш., вл. 3, 3А, 5, площадка | G23: Эксплуатация | H23: 01.07.2024 - 31.12.2026 | I23: =MAX(J23:P23) -> 63374747 | J23: 63374747 | R23: =SUM(S23:W23) -> 19781197 | S23: 19781197 | Z23: Продление
D24: №019346722 от 30.05.2024 | E24: объекты капитального строительства, расположенные на земельном (-ых) участке (-ах) с кадастровым (-и) номером (-ами): 77:07:0012008:4402, по адресу: г. Москва, Очаковское ш., вл. 3, 3а, 5, площадка | F24: г. Москва, Очаковское ш., вл. 3, 3А, 5, площадка | G24: Мобилизация | H24: 22.04.2024 - 30.06.2026 | I24: =MAX(J24:P24) -> 51161864 | J24: 48885480 | K24: 51161864 | R24: =SUM(S24:W24) -> 34782711 | S24: 33934562 | T24: 848148.69
D25: №020226119 от 10.10.2024 | E25: объекты капитального строительства, расположенные на земельном (-ых) участке (-ах) с кадастровым (-и) номером (-ами): 77:07:0012008:4402, по адресу: Очаковское ш., вл. 3, 3А, 5, площадка | F25: г. Москва, Очаковское ш., вл. 3, 3А, 5, площадка | G25: Электрика | H25: 02.09.2024 - 31.05.2026 | I25: =MAX(J25:P25) -> 6133744.2 | J25: 6133744.2 | R25: =SUM(S25:W25) -> 5795967.2 | S25: 5399130.1 | T25: 396837.13
A26: 3.6 | B26: ЖК Среда | D26: №018419783 от 25.12.2023 | E26: объекты капитального строительства, расположенные на земельном (-ых) участке (-ах) с кадастровым (-и) номером (-ами): -, по адресу: г. Москва, Очаковское ш., вл. 3, 3А, 5. | F26: г. Москва, Очаковское ш., вл. 3, 3А, 5, площадка | G26: Эксплуатация | H26: 01.01.2024- - 30.06.2026* | I26: =MAX(J26:P26) -> 27959055 | J26: 27959055 | R26: =SUM(S26:W26) -> 18115510 | S26: 18115510 | Z26: Продлен новым договором/ по факту все закрыто/ были ПМК, которые не обслуживали и КЛ/вода , также вышли в марте, июнь-июль 2024 простой, поэтому 4 месяца в остатке
D27: №023532811 от 14.05.2026 | F27: г. Москва, Очаковское ш., вл. 3, 3А, 5, Площадка (Среда) | G27: Эксплуатация | H27: 01.01.2026-31.12.2026 | I27: =MAX(J27:P27) -> 13929745 | J27: 13929745 | R27: =SUM(S27:W27) -> 0 | S27: 0 | Z27: смена адреса/продление/согласование договора
D28: №СК-МОБ/ОЧШ-5.1-5.8 от 14.03.2024 | E28: объекты капитального строительства, расположенные на земельном (-ых) участке (-ах) с кадастровым (-и) номером (-ами): 77:07:0012008:4413, по адресу: г. Москва, Очаковское ш., вл. 3, 3а, 5 | F28: г. Москва, Очаковское ш., вл. 3, 3А, 5, площадка | G28: Мобилизация | H28: 01.01.2024 -30.06.2026* | I28: =MAX(J28:P28) -> 44924741 | J28: 44924741 | R28: =SUM(S28:W28) -> 40985840 | S28: 40906831 | T28: 79009 | Z28: новые объемы по новому договору, остатки добираются по этому
D29: №023392699 от 17.04.2026 | E29: объекты капитального строительства, расположенные на земельном (-ых) участке (-ах) с кадастровым (-и) номером (-ами): 77:07:0012008:4413, по адресу: г. Москва, ЗАО, Очаково-Матвеевское, Очаковское ш. | F29: г. Москва, Очаковское ш., вл. 3, 3А, 5, Площадка (Среда) | G29: Мобилизация | H29: 27.03.2026 - 31.05.2026 | I29: =MAX(J29:P29) -> 347902.46 | J29: 347902.46 | R29: =SUM(S29:W29) -> 347902.46 | S29: 0 | T29: 347902.46 | Z29: смена адреса/ на подписании
A30: 3.7 | B30: ЖК Комфорт | D30: № 022769562 от 12.12.2025 года | E30: объекты капитального строительства, расположенные на земельном (-ых) участке (-ах) с кадастровым (-и) номером (-ами): 77:07:0012008:4421, по адресу: г. Москва, Очаковское ш., вл. 3, 3а, 5 | F30: г. Москва, Очаковское ш., вл. 3, 3А, 5, Площадка (Среда) | G30: Мобилизация | H30: 11.12.2025 - 31.05.2026 | I30: =MAX(J30:P30) -> 24983595 | J30: 24983595 | R30: =SUM(S30:W30) -> 0 | S30: 0 | Z30: Не начали работы , будет еще экспл.
A31: 4 | B31: Моментс (Красногорский, Волоколамское ш.) | C31: ООО "ПИК-УК" | I31: =SUM(I32) -> 47432904 | J31: =SUM(J32) -> 47432904 | K31: =SUM(K32) -> 0 | L31: =SUM(L32) -> 0 | M31: =SUM(M32) -> 0 | N31: =SUM(N32) -> 0 | O31: =SUM(O32) -> 0 | P31: =SUM(P32) -> 0 | Q31: =SUM(Q32) -> 0 | R31: =SUM(S31:W31) -> 45684204 | S31: =SUM(S32) -> 45684204 | T31: =SUM(T32) -> 0 | U31: =SUM(U32) -> 0 | V31: =SUM(V32) -> 0 | W31: =SUM(W32) -> 0 | X31: =SUM(X32) -> 0 | Y31: Алиев Абдулагат Алиевич/ Чалишев Фируз Талбакович
A32: 4.1 | B32: Площадка | D32: №СК/ВЛ-СДП от 01.03.2023 | E32: объекты капитального строительства, расположенные на земельном (-ых) участке (-ах) с кадастровым (-и) номером (-ами): 77:08:0009002:1000, по адресу: г. Москва, Волоколамское ш., вл. 28, площадка. | F32: г. Москва, Волоколамское ш., вл. 28, площадка | G32: Эксплуатация | H32: 01.03.2023 - 31.03.2026 | I32: =MAX(J32:P32) -> 47432904 | J32: 47432904 | R32: =SUM(S32:W32) -> 45684204 | S32: 45684204 | Z32: Только эксплуатация
A33: 5 | B33: Саларьево парк | C33: ООО "ПИК-МЕНЕДЖМЕНТ" | I33: =SUM(I34:I43) -> 2.3292797e+08 | J33: =SUM(J34:J43) -> 2.2894123e+08 | K33: =SUM(K34:K43) -> 55222907 | L33: =SUM(L34:L43) -> 0 | M33: =SUM(M34:M43) -> 0 | N33: =SUM(N34:N43) -> 0 | O33: =SUM(O34:O43) -> 0 | P33: =SUM(P34:P43) -> 0 | Q33: =SUM(Q34:Q43) -> 0 | R33: =SUM(S33:W33) -> 1.3289143e+08 | S33: =SUM(S34:S43) -> 1.2488423e+08 | T33: =SUM(T34:T43) -> 8007197.7 | U33: =SUM(U34:U43) -> 0 | V33: =SUM(V34:V43) -> 0 | W33: =SUM(W34:W43) -> 0 | X33: =SUM(X34:X43) -> 0 | Y33: Петропавловских Александр Павлович/-
A34: 5.1 | B34: 83 корпус | D34: №020545364 от 26.11.2024 | E34: объект капитального строительства: «Многоэтажный жилой дом, корпус 83 с подземной стоянкой автомобилей, с инженерными сетями, в составе Жилой застройки с объектами социальной инфраструктуры» по адресу: Москва, НАО, вн.тер.г. поселение, г. Москва, Московский, улица Саларьевская, земельный участок 17 | F34: д. Саларьево, 14- очередь, корпус 83 | G34: Мобилизация | H34: 08.10.2024 -30.06.2026* | I34: =MAX(J34:P34) -> 25582776 | J34: 25161404 | K34: 25582776 | R34: =SUM(S34:W34) -> 23058124 | S34: 23058124
D35: №021299329 от 24.03.2025 | E35: объект капитального строительства: «Многоэтажный жилой дом, корпус 83 с подземной стоянкой автомобилей, с инженерными сетями, в составе Жилой застройки с объектами социальной инфраструктуры» по адресу: Москва, НАО, вн.тер.г. поселение, г. Москва, Московский, улица Саларьевская, земельный участок 17 | F35: д. Саларьево, 14 очередь, корп. 83 | G35: Эксплуатация | H35: 01.01.2026-31.12.2026 | I35: =MAX(J35:P35) -> 30729117 | J35: 30729117 | R35: =SUM(S35:W35) -> 19787637 | S35: 18430204 | T35: 1357433.2
A36: 5.2 | B36: 74 корпус | D36: № 022039867 от 11.08.2025 года | E36: объекты капитального строительства, расположенные на земельном (-ых) участке (-ах) с кадастровым (-и) номером (-ами): 77:17:0110205:17424, 77:17:0110205:17418, 77:17:0110205:17420, по адресу: г. Москва, п. Московский, д. Саларьево | F36: д. Саларьево, 13 очередь | G36: Мобилизация | H36: 11.06.2025 - 30.06.2026 | I36: =MAX(J36:P36) -> 14060669 | J36: 14060669 | R36: =SUM(S36:W36) -> 3414911 | S36: 2491884.8 | T36: 923026.17 | Z36: вышел ДС
D37: № 022086879 от 19.08.2025 года | E37: объект капитального строительства: «Многоэтажный жилой дом, корпус 74 с подземной стоянкой автомобилей, с инженерными сетями, в составе Жилой застройки с объектами социальной инфраструктуры» по адресу: Москва, НАО, вн.тер.г. муниципальный округ, г. Москва, Коммунарка, улица Трёхполье, земельный участок 7 | F37: д. Саларьево, 13 очередь, корп. 74 | G37: Эксплуатация | H37: 01.06.2025-31.12.2026 | I37: =MAX(J37:P37) -> 29506540 | J37: 29506540 | R37: =SUM(S37:W37) -> 15487868 | S37: 14000863 | T37: 1487004.4
A38: 5.3 | B38: 57 корпус | D38: №021777580 от 20.06.2025 года | E38: объект капитального строительства: Корпус 57 (этап 1), входящий в состав имущественного комплекса: ««Многоэтажный жилой дом, корпус 57, с инженерными сетями, в составе Жилой застройки с объектами социальной инфраструктуры» Адрес объекта: г. Москва, п. Сосенское, вблизи д. Николо-Хованское. Этап 1» по адресу: Москва, НАО, поселение, г. Москва, Сосенское, вблизи д. Николо-Хованское | F38: д. Саларьево, 11 очередь, корп. 57 | G38: Мобилизация | H38: 29.05.2025 - 31.05.2026 | I38: =MAX(J38:P38) -> 29640132 | J38: 26074763 | K38: 29640132 | R38: =SUM(S38:W38) -> 20672517 | S38: 19287430 | T38: 1385087.4
D39: № 022427735 от 14.11.2025 года | E39: объекты капитального строительства, расположенные на земельном (-ых) участке (-ах) с кадастровым (-и) номером (-ами): 77:17:0120114:6123, по адресу: г. Москва, п Сосенское, вблизи д. Николо-Хованское | F39: д. Саларьево, площадка | G39: Эксплуатация | H39: 01.07.2025-31.12.2026 | I39: =MAX(J39:P39) -> 31238625 | J39: 31238625 | R39: =SUM(S39:W39) -> 17049676 | S39: 15297244 | T39: 1752431.4
A40: 5.4 | B40: 69 корпус | D40: № 022298241 от 29.09.2025 года | E40: объект капитального строительства: корп. 69 (этап 1), входящий в состав имущественного комплекса: «Многоэтажный жилой дом, корпус 69 с подземной стоянкой автомобилей, с инженерными сетями, в составе Жилой застройки с объектами социальной инфраструктуры. 1 этап (секции 1, 2, 3, 4, 5, 6, 7)» по адресу: Москва, НАО, вн.тер.г. муниципальный округ, г. Москва, Коммунарка, улица Трёхполье, земельный участок 7 | F40: д. Саларьево, 13 очередь, корп. 69 | G40: Мобилизация | H40: 08.09.2025 - 30.06.2026* | I40: =MAX(J40:P40) -> 37903822 | J40: 37903822 | R40: =SUM(S40:W40) -> 20414612 | S40: 20414612
...

Sheet Компенсации
A1: 1
A2: № п/п | B2: Объект | C2: Дата документа/ период (материалы) | D2: Номер | E2: Наименование | F2: Сумма компенсации | G2: Ресурс | H2: Дата получения | I2: Путь к файлу | J2: Принято/ отклонено | K2: Компенсация | L2: Ответственное лицо | M2: Способ компенсации | N2: Плановый срок получения компенсации | O2: Статус на текущую дату | P2: Дата получения компенсации | Q2: Примечание
A3: 1 | B3: Кольская, 8 | C3: 46226 | D3: 292/1-2887-И | E3: Претензия о выплате затрат на устранение недостатков | F3: 100000 | G3: Диадок | H3: 46226.45 | I3: Z:\ПТО СКАЛА\ШТРАФЫ тест\Кольская 8 | J3: Принято | K3: Предусмотрена | M3: Компенсация путем закрытия 500 м3 дополнительной уборки снега | O3: Подготовка документов в ПТО | Q3: Компенсация получена с КС №13 по договору № ??? в январе 2030г.
A4: 2 | B4: Обручева 27 | E4: Превышение стоимости закупки плит относительно сметы | F4: =60000+135000 -> 195000 | J4: Отклонено | K4: Предусмотрена | N4: октябрь 2026 | O4: Подготовка документов в ПТО
A5: 3 | B5: Зеленоград | C5: 08.2025-07.2026 | E5: Компенсация стоимости плит 2П30 и ПАГ-14 | F5: Собираем УПД для сверки | I5: Z:\ПТО СКАЛА\3. Объекты\Зеленоград ЦИЭ\6. Компенсации\Компенсация плит, июль 2026 | J5: В работе | K5: Предусмотрена | M5: Акт сверки стоимости материалов | N5: ноябрь 2026 | O5: Подготовка документов в ПТО
A6: 4 | B6: Рассказовка Ф18 к.1 | C6: 46211 | D6: 507-1585/26-ИСХ | E6: Штраф | F6: 100000 | G6: Диадок | I6: https://myabs.absgroup.ru/control/ordinance
A7: 5 | B7: Рассказовка Ф13 к.1 | C7: 46202 | D7: 507-1463/26-ИСХ | E7: ШТРАФ | F7: 50000 | G7: Диадок | H7: 46252
A8: 6 | B8: Рассказовка Ф13 к.1 | C8: 46202 | D8: 507-1469/26-ИСХ | E8: ШТРАФ | F8: 50000 | G8: Диадок | H8: 46252
A9: 7 | B9: Рассказовка Ф13 к.1 | C9: 46202 | D9: 507-1468/26-ИСХ | E9: ШТРАФ | F9: 50000 | G9: Диадок | H9: 46252
A10: 8 | B10: Рассказовка Ф13 к.1 | C10: 46202 | D10: 507-1450/26-ИСХ | E10: ШТРАФ | F10: 50000 | G10: Диадок | H10: 46252
A11: 9 | B11: Рассказовка Ф13 к.1 | C11: 46202 | D11: 507-1467/26-ИСХ | E11: ШТРАФ | F11: 50000 | G11: Диадок | H11: 46252
A12: 10 | B12: Рассказовка Ф13 к.1 | C12: 46202 | D12: 507-1459/26-ИСХ | E12: ШТРАФ | F12: 50000 | G12: Диадок | H12: 46252
A13: 11 | B13: Рассказовка Ф13 к.1 | C13: 46202 | D13: 507-1460/26-ИСХ | E13: ШТРАФ | F13: 50000 | G13: Диадок | H13: 46252

Sheet 07.26
